Workbook
Name Slicer_Category: #N/A
Name Slicer_Region1: #N/A
Name Slicer_Sales_Channel: #N/A
Name Timeline_OrderDate: #N/A

Sheet Raw Dataset
A1: OrderID | B1: OrderDate | C1: CustomerID | D1: FirstName | E1: LastName | F1: Age | G1: City | H1: Region | I1: ProductID | J1: ProductName | K1: Category | L1: Price | M1: Quantity | N1: TotalAmount
A2: 1 | B2: 45808 | C2: 96 | D2: Mary | E2: Nwosu | F2: 69 | G2: Enugu | H2: South East | I2: 23 | J2: Mechanical Keyboard | K2: Gaming | L2: 195.22 | M2: 4 | N2: 780.88
A3: 2 | B3: 45853 | C3: 42 | D3: Ada | E3: Eze | F3: 45 | G3: Port Harcourt | H3: South South | I3: 27 | J3: Water Bottle | K3: Lifestyle | L3: 845 | M3: 4 | N3: 3380
A4: 3 | B4: 45454 | C4: 104 | D4: Amina | E4: Adeyemi | F4: 56 | G4: Port Harcourt | H4: South South | I4: 3 | J4: Tablet | K4: Electronics | L4: 922.74 | M4: 6 | N4: 5536.44
A5: 4 | B5: 45778 | C5: 14 | D5: Grace | E5: Mensah | F5: 67 | G5: Lagos | H5: South West | I5: 2 | J5: Smartphone | K5: Electronics | L5: 1476.14 | M5: 4 | N5: 5904.56
A6: 5 | B6: 45557 | C6: 72 | D6: David | E6: Ibrahim | F6: 43 | G6: Enugu | H6: South East | I6: 12 | J6: Microwave | K6: Home Appliances | L6: 1036.12 | M6: 2 | N6: 2072.24
A7: 6 | B7: 45944 | C7: 119 | D7: Chinedu | E7: Mensah | F7: 61 | G7: Enugu | H7: South East | I7: 13 | J7: Electric Kettle | K7: Home Appliances | L7: 1340.6 | M7: 3 | N7: 4021.8
A8: 7 | B8: 45825 | C8: 113 | D8: Grace | E8: Balogun | F8: 29 | G8: Lagos | H8: South West | I8: 17 | J8: Desk Lamp | K8: Office | L8: 339.98 | M8: 4 | N8: 1359.92
A9: 8 | B9: 45933 | C9: 102 | D9: Ibrahim | E9: Okoro | F9: 50 | G9: Port Harcourt | H9: South South | I9: 24 | J9: Gaming Mouse | K9: Gaming | L9: 213.01 | M9: 2 | N9: 426.02
A10: 9 | B10: 45573 | C10: 105 | D10: Emeka | E10: Adebayo | F10: 45 | G10: Enugu | H10: South East | I10: 4 | J10: Headphones | K10: Electronics | L10: 1156.21 | M10: 4 | N10: 4624.84
A11: 10 | B11: 45371 | C11: 46 | D11: David | E11: Adeyemi | F11: 39 | G11: Kano | H11: SOUTH WEST | I11: 12 | J11: Microwave | K11: Home Appliances | L11: 1036.12 | M11: 6 | N11: 6216.72
A12: 11 | B12: 45584 | C12: 95 | D12: Kemi | E12: Nwosu | F12: 19 | G12: Abuja | H12: North Central | I12: 26 | J12: Backpack | K12: Lifestyle | L12: 803.73 | M12: 2 | N12: 1607.46
A13: 12 | B13: 45570 | C13: 32 | D13: Chinedu | E13: Ibrahim | F13: 45 | G13: Enugu | H13: South East | I13: 26 | J13: Backpack | K13: Lifestyle | L13: 803.73 | M13: 3 | N13: 2411.19
... A28: 27 | B28: 45298 | C28: 104 | D28: Amina | E28: Adeyemi | F28: 56 | G28: Port Harcourt | H28: South South | I28: 10 | J28: Laptop Bag | K28: Accessories | L28: 608.48 | M28: 3 | N28: 1825.44
A29: 28 | B29: 45597 | C29: 114 | D29: Ngozi | E29: Yakubu | F29: unknown | G29: Port Harcourt | H29: South South | I29: 27 | J29: Water Bottle | K29: Lifestyle | L29: 845 | M29: 4 | N29: 3380
A30: 29 | B30: 45721 | C30: 42 | D30: Ada | E30: Eze | F30: 45 | G30: Port Harcourt | H30: South South | I30: 23 | J30: Mechanical Keyboard | K30: Gaming | L30: 195.22 | M30: 5 | N30: 976.1
A31: 30 | B31: 45851 | C31: 2 | D31: Blessing | E31: Balogun | F31: 24 | G31: Kano | H31: North West | I31: 30 | J31: Travel Adapter | K31: Lifestyle | L31: 672.22 | M31: 5 | N31: 3361.1
A32: 31 | B32: 45517 | C32: 60 | D32: Chinedu | E32: Mensah | F32: 28 | G32: Lagos | H32: South-West | I32: 4 | J32: Headphones | K32: Electronics | L32: 1156.21 | M32: 4 | N32: 4624.84
A33: 32 | B33: 45516 | C33: 29 | D33: Ngozi | E33: Nwosu | F33: 56 | G33: Ibadan | H33: South West | I33: 1 | J33: Laptop | K33: Electronics | L33: 83.63 | M33: 3 | N33: 250.89
A34: 33 | B34: 45738 | C34: 114 | D34: Ngozi | E34: Yakubu | F34: 18 | G34: Port Harcourt | H34: South South | I34: 18 | J34: Webcam | K34: Office | L34: 1209.1 | M34: 4 | N34: 4836.4
A35: 34 | B35: 45321 | C35: 4 | D35: David | E35: Mensah | F35: 50 | G35: Ibadan | H35: South West | I35: 17 | J35: Desk Lamp | K35: Office | L35: 339.98 | M35: 4 | N35: 1359.92
A36: 35 | B36: 45636 | C36: 11 | D36: Emeka | E36: Osei | F36: 52 | G36: Lagos | H36: South West | I36: 10 | J36: Laptop Bag | K36: Accessories | L36: 608.48 | M36: 6 | N36: 3650.88
A37: 36 | B37: 45987 | C37: 67 | D37: Amina | E37: Yakubu | F37: 23 | G37: Abuja | H37: North Central | I37: 29 | J37: Bluetooth Speaker | K37: Lifestyle | L37: 1136.55 | M37: 4 | N37: 4546.2
A38: 37 | B38: 45461 | C38: 45 | D38: Samuel | E38: Yakubu | F38: 46 | G38: Enugu | H38: South East | I38: 30 | J38: Travel Adapter | K38: Lifestyle | L38: 672.22 | M38: 4 | N38: 2688.88
A39: 38 | B39: 45422 | C39: 91 | D39: Kemi | E39: Okafor | F39: 40 | G39: Enugu | H39: South East | I39: 4 | J39: Headphones | K39: Electronics | L39: 1156.21 | M39: 5 | N39: 5781.05
A40: 39 | B40: 45838 | C40: 102 | D40: Ibrahim | E40: Okoro | F40: 50 | G40: Port Harcourt | H40: South South | I40: 30 | J40: Travel Adapter | K40: Lifestyle | L40: 672.22 | M40: 1 | N40: 672.22
A41: 40 | B41: 45695 | C41: 82 | D41: David | E41: Okoro | F41: 58 | G41: Enugu | H41: South East | I41: 30 | J41: Travel Adapter | K41: Lifestyle | L41: 672.22 | M41: 5 | N41: 3361.1
... A69: 68 | B69: 45610 | C69: 32 | D69: Chinedu | E69: Ibrahim | F69: 45 | G69: Enugu | H69: South East | I69: 11 | J69: Blender | K69: home appliances | L69: 234.14 | M69: 1 | N69: 234.14
A70: 69 | B70: 45884 | C70: 9 | D70: Chinedu | E70: Adeyemi | F70: 42 | G70: Enugu | I70: 1 | J70: Laptop | K70: Electronics | L70: 83.63 | M70: 1 | N70: 83.63
A71: 70 | B71: 45611 | C71: 62 | D71: Blessing | E71: Nwosu | F71: 18 | G71: Lagos | H71: South West | I71: 21 | J71: Game Controller | K71: Gaming | L71: 842.75 | M71: 5 | N71: 4213.75
A72: 71 | B72: 45985 | C72: 37 | D72: Kemi | E72: Adebayo | F72: 69 | G72: Ibadan | H72: South West | I72: 5 | J72: Smartwatch | K72: Electronics | L72: 691.29 | M72: 4 | N72: 2765.16
A73: 72 | B73: 45698 | C73: 110 | D73: Emeka | E73: Ibrahim | F73: 50 | G73: Ibadan | H73: South West | I73: 13 | J73: Electric Kettle | K73: Home Appliances | L73: 1340.6 | M73: 6 | N73: 8043.6
A74: 73 | B74: 45495 | C74: 106 | D74: Ngozi | E74: Eze | F74: 30 | G74: Ibadan | H74: South West | I74: 1 | J74: Laptop | K74: Electronics | L74: 83.63 | M74: 1 | N74: 83.63
A75: 74 | B75: 45898 | C75: 52 | D75: Chinedu | E75: Adeyemi | F75: 60 | G75: Kano | H75: South-West | I75: 10 | J75: Laptop Bag | K75: Accessories | L75: 608.48 | M75: 6 | N75: 3650.88
A76: 75 | B76: 45934 | C76: 23 | D76: David | E76: Okoro | F76: 49 | G76: Enugu | H76: South East | I76: 3 | J76: Tablet | K76: Electronics | L76: 922.74 | M76: 2 | N76: 1845.48
A77: 76 | B77: 45396 | C77: 31 | D77: Grace | E77: Yakubu | F77: 66 | G77: Ibadan | H77: South West | I77: 10 | J77: Laptop Bag | K77: Accessories | L77: 608.48 | M77: 6 | N77: 3650.88
A78: 77 | B78: 45600 | C78: 6 | D78: David | E78: Osei | F78: 55 | G78: Lagos | H78: South West | I78: 13 | J78: Electric Kettle | K78: Home Appliances | L78: 1340.6 | M78: 6 | N78: 8043.6
A79: 78 | B79: 45906 | C79: 82 | D79: David | E79: Okoro | F79: 58 | G79: Enugu | H79: South East | I79: 26 | J79: Backpack | K79: Lifestyle | L79: 803.73 | M79: 1 | N79: 803.73
A80: 79 | B80: 45871 | C80: 48 | D80: David | E80: Adeyemi | F80: 20 | G80: Lagos | H80: South West | I80: 13 | J80: Electric Kettle | K80: Home Appliances | L80: 1340.6 | M80: 1 | N80: 1340.6
A81: 80 | B81: 45647 | C81: 113 | D81: Grace | E81: Balogun | F81: 29 | G81: Lagos | H81: South West | I81: 30 | J81: Travel Adapter | K81: Lifestyle | L81: 672.22 | M81: 5 | N81: 3361.1
...

Sheet Change log
A1: ID | B1: Issue | C1: Field | D1: Action | E1: Rows | F1: Status
A2: C01 | B2: Duplicate orders | C2: All | D2: Removed (Remove Duplicates) | E2: 12 | F2: Done
A3: C02 | B3: Region spelling variants | C3: Region | D3: Standardised to "South West" | E3: 14 | F3: Done
A4: C03 | B4: Blank region | C4: Region | D4: Filled from City | E4: 4 | F4: Done
A5: C04 | B5: Category case and spaces | C5: Category | D5: Trimmed, standardised | E5: 500 | F5: Done
A6: C05 | B6: Spaces in first names | C6: FirstName | D6: Trimmed | E6: 15 | F6: Done
A7: C06 | B7: Negative prices | C7: Price | D7: Investigated and made positive | E7: 8 | F7: Done
A8: C07 | B8: Age "unknown" or blank | C8: Age | D8: Used customer's other orders | E8: 7 | F8: Done
A9: C08 | B9: Blank, inconsistent, and Impossible ages (0,150,unknown,blank) | C9: Age | D9: Used customer's other orders | E9: 3 | F9: Done
A10: C09 | B10: No full name | C10: FullName | D10: Joined first and last name | E10: 500 | F10: Done
A11: C10 | B11: No month field | C11: Month | D11: Created from OrderDate | E11: 500 | F11: Done
A12: C11 | B12: No year field | C12: Year | D12: Created from OrderDate | E12: 500 | F12: Done
A13: C12 | B13: Field name | C13: Total Amount | D13: Renamed TotalAmount to Revenue ; Recalculated as Price x Quantity | E13: 500 | F13: Done
... A17: C16 | B17: Wrong Format | C17: Quantity, Age | D17: Formatted as Number | E17: 500 | F17: Done

Sheet Processed Data
A1: OrderID | B1: OrderDate | C1: Month | D1: year | E1: CustomerID | F1: FullName | G1: Age | H1: City | I1: Region | J1: ProductID | K1: ProductName | L1: Category | M1: Price | N1: Quantity | O1: Revenue | P1: Sales Channel
A2: 1 | B2: 45808 | C2: =TEXT(B2,"mmm") -> May | D2: =YEAR(B2) -> 2025 | E2: 96 | F2: Mary Nwosu | G2: 69 | H2: Enugu | I2: South East | J2: 23 | K2: Mechanical Keyboard | L2: Gaming | M2: 195.22 | N2: 4 | O2: =M2*N2 -> 780.88 | P2: Corporate Sales
A3: 2 | B3: 45853 | C3: =TEXT(B3,"mmm") -> Jul | D3: =YEAR(B3) -> 2025 | E3: 42 | F3: Ada Eze | G3: 45 | H3: Port Harcourt | I3: South South | J3: 27 | K3: Water Bottle | L3: Lifestyle | M3: 845 | N3: 4 | O3: =M3*N3 -> 3380 | P3: Marketplace
A4: 3 | B4: 45454 | C4: =TEXT(B4,"mmm") -> Jun | D4: =YEAR(B4) -> 2024 | E4: 104 | F4: Amina Adeyemi | G4: 56 | H4: Port Harcourt | I4: South South | J4: 3 | K4: Tablet | L4: Electronics | M4: 922.74 | N4: 6 | O4: =M4*N4 -> 5536.44 | P4: Online
A5: 4 | B5: 45778 | C5: =TEXT(B5,"mmm") -> May | D5: =YEAR(B5) -> 2025 | E5: 14 | F5: Grace Mensah | G5: 67 | H5: Lagos | I5: South West | J5: 2 | K5: Smartphone | L5: Electronics | M5: 1476.14 | N5: 4 | O5: =M5*N5 -> 5904.56 | P5: Retail Store
A6: 5 | B6: 45557 | C6: =TEXT(B6,"mmm") -> Sept | D6: =YEAR(B6) -> 2024 | E6: 72 | F6: David Ibrahim | G6: 43 | H6: Enugu | I6: South East | J6: 12 | K6: Microwave | L6: Home Appliances | M6: 1036.12 | N6: 2 | O6: =M6*N6 -> 2072.24 | P6: Corporate Sales | S6: DESCRIPTIVE STATISTICS(Analysis ToolPak)
A7: 6 | B7: 45944 | C7: =TEXT(B7,"mmm") -> Oct | D7: =YEAR(B7) -> 2025 | E7: 119 | F7: Chinedu Mensah | G7: 61 | H7: Enugu | I7: South East | J7: 13 | K7: Electric Kettle | L7: Home Appliances | M7: 1340.6 | N7: 3 | O7: =M7*N7 -> 4021.8 | P7: Online | S7: AGE | T7: Age Stats | U7: Price | V7: Price Stats | W7: Quantity | X7: Quantity Stats | Y7: Revenue | Z7: Revenue stats
A8: 7 | B8: 45825 | C8: =TEXT(B8,"mmm") -> Jun | D8: =YEAR(B8) -> 2025 | E8: 113 | F8: Grace Balogun | G8: 29 | H8: Lagos | I8: South West | J8: 17 | K8: Desk Lamp | L8: Office | M8: 339.98 | N8: 4 | O8: =M8*N8 -> 1359.92 | P8: Retail Store | S8: Mean | T8: 43.656 | U8: Mean | V8: 859.0801 | W8: Mean | X8: 3.526 | Y8: Mean | Z8: 3037.7435
A9: 8 | B9: 45933 | C9: =TEXT(B9,"mmm") -> Oct | D9: =YEAR(B9) -> 2025 | E9: 102 | F9: Ibrahim Okoro | G9: 50 | H9: Port Harcourt | I9: South South | J9: 24 | K9: Gaming Mouse | L9: Gaming | M9: 213.01 | N9: 2 | O9: =M9*N9 -> 426.02 | P9: Retail Store | S9: Median | T9: 45 | U9: Median | V9: 845 | W9: Median | X9: 4 | Y9: Median | Z9: 2671.51
A10: 9 | B10: 45573 | C10: =TEXT(B10,"mmm") -> Oct | D10: =YEAR(B10) -> 2024 | E10: 105 | F10: Emeka Adebayo | G10: 45 | H10: Enugu | I10: South East | J10: 4 | K10: Headphones | L10: Electronics | M10: 1156.21 | N10: 4 | O10: =M10*N10 -> 4624.84 | P10: Marketplace | S10: Standard Deviation | T10: 15.358 | U10: Standard Deviation | V10: 394.77851 | W10: Standard Deviation | X10: 1.692055 | Y10: Standard Deviation | Z10: 2128.1808
A11: 10 | B11: 45371 | C11: =TEXT(B11,"mmm") -> Mar | D11: =YEAR(B11) -> 2024 | E11: 46 | F11: David Adeyemi | G11: 39 | H11: Kano | I11: North West | J11: 12 | K11: Microwave | L11: Home Appliances | M11: 1036.12 | N11: 6 | O11: =M11*N11 -> 6216.72 | P11: Marketplace | S11: Skewness | T11: 0.0355 | U11: Skewness | V11: -0.33169173 | W11: Skewness | X11: -0.039952742 | Y11: Skewness | Z11: 0.64986443
A12: 11 | B12: 45584 | C12: =TEXT(B12,"mmm") -> Oct | D12: =YEAR(B12) -> 2024 | E12: 95 | F12: Kemi Nwosu | G12: 19 | H12: Abuja | I12: North Central | J12: 26 | K12: Backpack | L12: Lifestyle | M12: 803.73 | N12: 2 | O12: =M12*N12 -> 1607.46 | P12: Marketplace | S12: Minimum | T12: 18 | U12: Minimum | V12: 83.63 | W12: Minimum | X12: 1 | Y12: Minimum | Z12: 83.63
A13: 12 | B13: 45570 | C13: =TEXT(B13,"mmm") -> Oct | D13: =YEAR(B13) -> 2024 | E13: 32 | F13: Chinedu Ibrahim | G13: 45 | H13: Enugu | I13: South East | J13: 26 | K13: Backpack | L13: Lifestyle | M13: 803.73 | N13: 3 | O13: =M13*N13 -> 2411.19 | P13: Marketplace | S13: Maximum | T13: 69 | U13: Maximum | V13: 1476.14 | W13: Maximum | X13: 6 | Y13: Maximum | Z13: 8264.64
A14: 13 | B14: 45619 | C14: =TEXT(B14,"mmm") -> Nov | D14: =YEAR(B14) -> 2024 | E14: 54 | F14: Grace Okoro | G14: 59 | H14: Lagos | I14: South West | J14: 11 | K14: Blender | L14: Home Appliances | M14: 234.14 | N14: 5 | O14: =M14*N14 -> 1170.7 | P14: Online | S14: Sum | T14: 21828 | U14: Sum | V14: 429540.05 | W14: Sum | X14: 1763 | Y14: Sum | Z14: 1518871.8
A15: 14 | B15: 45374 | C15: =TEXT(B15,"mmm") -> Mar | D15: =YEAR(B15) -> 2024 | E15: 8 | F15: Fatima Bello | G15: 31 | H15: Enugu | I15: South East | J15: 20 | K15: External Drive | L15: Office | M15: 704.86 | N15: 2 | O15: =M15*N15 -> 1409.72 | P15: Retail Store | S15: Count | T15: 500 | U15: Count | V15: 500 | W15: Count | X15: 500 | Y15: Count | Z15: 500
A16: 15 | B16: 45446 | C16: =TEXT(B16,"mmm") -> Jun | D16: =YEAR(B16) -> 2024 | E16: 103 | F16: Amina Adeyemi | G16: 34 | H16: Enugu | I16: South East | J16: 27 | K16: Water Bottle | L16: Lifestyle | M16: 845 | N16: 2 | O16: =M16*N16 -> 1690 | P16: Marketplace
A17: 16 | B17: 45684 | C17: =TEXT(B17,"mmm") -> Jan | D17: =YEAR(B17) -> 2025 | E17: 95 | F17: Kemi Nwosu | G17: 19 | H17: Abuja | I17: North Central | J17: 23 | K17: Mechanical Keyboard | L17: Gaming | M17: 195.22 | N17: 6 | O17: =M17*N17 -> 1171.32 | P17: Corporate Sales
A18: 17 | B18: 45448 | C18: =TEXT(B18,"mmm") -> Jun | D18: =YEAR(B18) -> 2024 | E18: 56 | F18: David Mensah | G18: 30 | H18: Ibadan | I18: South West | J18: 13 | K18: Electric Kettle | L18: Home Appliances | M18: 1340.6 | N18: 6 | O18: =M18*N18 -> 8043.6 | P18: Corporate Sales | S18: OUTLIERS CHECK | Y18: KPIS | Z18: Total | AA18: 2024 | AB18: 2025 | AC18: YoY Groth Rate
A19: 18 | B19: 45511 | C19: =TEXT(B19,"mmm") -> Aug | D19: =YEAR(B19) -> 2024 | E19: 75 | F19: Chinedu Yakubu | G19: 31 | H19: Ibadan | I19: South West | J19: 25 | K19: Console Stand | L19: Gaming | M19: 705 | N19: 1 | O19: =M19*N19 -> 705 | P19: Online | S19: . | T19: Age | U19: Price | V19: Quantity | W19: Revenue | Y19: Total Revenue | Z19: =SUM(O2:O501) -> 1518871.8 | AA19: =SUMIF(D2:D501, 2024,O2:O501) -> 695223.11 | AB19: =SUMIF(D2:D501, 2025,O2:O501) -> 823648.65 | AC19: =Analysis!H77 -> 0.18472565
A20: 19 | B20: 45716 | C20: =TEXT(B20,"mmm") -> Feb | D20: =YEAR(B20) -> 2025 | E20: 91 | F20: Kemi Okafor | G20: 40 | H20: Enugu | I20: South East | J20: 13 | K20: Electric Kettle | L20: Home Appliances | M20: 1340.6 | N20: 4 | O20: =M20*N20 -> 5362.4 | P20: Marketplace | S20: Q1 | T20: =_xlfn.QUARTILE.INC($G$2:G501,1) -> 30 | U20: =_xlfn.QUARTILE.INC($M$2:M501,1) -> 608.48 | V20: =_xlfn.QUARTILE.INC($N$2:N501,1) -> 2 | W20: =_xlfn.QUARTILE.INC(O2:O501,1) -> 1170.42 | Y20: Average Order value | Z20: =AVERAGE(O2:O501) -> 3037.7435 | AA20: =AVERAGEIF(D2:D501, 2024,O2:O501) -> 2958.3962 | AB20: =AVERAGEIF(D2:D501, 2025,O2:O501) -> 3108.1081 | AC20: =Analysis!H79 -> 0.050605764
A21: 20 | B21: 45630 | C21: =TEXT(B21,"mmm") -> Dec | D21: =YEAR(B21) -> 2024 | E21: 55 | F21: Ngozi Balogun | G21: 39 | H21: Lagos | I21: South West | J21: 16 | K21: Printer | L21: Office | M21: 1170.95 | N21: 5 | O21: =M21*N21 -> 5854.75 | P21: Corporate Sales | S21: Q3 | T21: =_xlfn.QUARTILE.INC($G$2:G501,3) -> 56 | U21: =_xlfn.QUARTILE.INC($M$2:M501,3) -> 1170.95 | V21: =_xlfn.QUARTILE.INC($N$2:N501,3) -> 5 | W21: =_xlfn.QUARTILE.INC($O2:O501,3) -> 4229.37 | Y21: Total Orders | Z21: =COUNT(A2:A501) -> 500 | AA21: =COUNTIF(D2:D501, 2024) -> 235 | AB21: =COUNTIF(D2:D501, 2025) -> 265 | AC21: =Analysis!H81 -> 0.12765957
A22: 21 | B22: 45769 | C22: =TEXT(B22,"mmm") -> Apr | D22: =YEAR(B22) -> 2025 | E22: 91 | F22: Kemi Okafor | G22: 40 | H22: Enugu | I22: South East | J22: 16 | K22: Printer | L22: Office | M22: 1170.95 | N22: 4 | O22: =M22*N22 -> 4683.8 | P22: Retail Store | S22: IQR | T22: =T21-T20 -> 26 | U22: =U21-U20 -> 562.47 | V22: =V21-V20 -> 3 | W22: =W21-W20 -> 3058.95 | Y22: Total Quantity | Z22: =SUM(N2:N501) -> 1763 | AA22: =SUMIF(D2:D501, 2024,N2:N501) -> 815 | AB22: =SUMIF(D2:D501, 2025,N2:N501) -> 948 | AC22: =Analysis!H83 -> 0.16319018
A23: 22 | B23: 45355 | C23: =TEXT(B23,"mmm") -> Mar | D23: =YEAR(B23) -> 2024 | E23: 27 | F23: Chinedu Okafor | G23: 25 | H23: Abuja | I23: North Central | J23: 29 | K23: Bluetooth Speaker | L23: Lifestyle | M23: 1136.55 | N23: 2 | O23: =M23*N23 -> 2273.1 | P23: Online | S23: Lower fence | T23: =T20-1.5*T22 -> -9 | U23: =U20-1.5*U22 -> -235.225 | V23: =V20-1.5*V22 -> -2.5 | W23: =W20-1.5*W22 -> -3418.005 | Y23: Total Customers | Z23: =Analysis!E56 -> 117 | AA23: =Analysis!F77 -> 103 | AB23: =Analysis!F78 -> 111 | AC23: =Analysis!H85 -> 0.077669903
A24: 23 | B24: 45722 | C24: =TEXT(B24,"mmm") -> Mar | D24: =YEAR(B24) -> 2025 | E24: 79 | F24: Kemi Okoro | G24: 24 | H24: Port Harcourt | I24: South South | J24: 21 | K24: Game Controller | L24: Gaming | M24: 842.75 | N24: 4 | O24: =M24*N24 -> 3371 | P24: Marketplace | S24: Upper Fence | T24: =T21+1.5*T22 -> 95 | U24: =U21+1.5*U22 -> 2014.655 | V24: =V21+1.5*V22 -> 9.5 | W24: =W21+1.5*W22 -> 8817.795
A25: 24 | B25: 45890 | C25: =TEXT(B25,"mmm") -> Aug | D25: =YEAR(B25) -> 2025 | E25: 53 | F25: Ngozi Nwosu | G25: 47 | H25: Enugu | I25: South East | J25: 15 | K25: Air Conditioner | L25: Home Appliances | M25: 1329.92 | N25: 6 | O25: =M25*N25 -> 7979.52 | P25: Online | S25: OUTLIERS | T25: =COUNTIF($G$2:$G$501, "<" & T23)+ COUNTIF($G$2:$G$501, ">" & T24) -> 0 | U25: =COUNTIF($M$2:$M$501,"<"&U23)+ COUNTIF($M$2:$M$501,">"&U24) -> 0 | V25: =COUNTIF($N$2:$N$501, "<" & V23)+ COUNTIF($N$2:$N$501, ">" & V24) -> 0 | W25: =COUNTIF($O$2:$O$501, "<" & W23)+ COUNTIF($O$2:$O$501, ">" & W24) -> 0
A26: 25 | B26: 45312 | C26: =TEXT(B26,"mmm") -> Jan | D26: =YEAR(B26) -> 2024 | E26: 22 | F26: Fatima Adeyemi | G26: 31 | H26: Lagos | I26: South West | J26: 18 | K26: Webcam | L26: Office | M26: 1209.1 | N26: 5 | O26: =M26*N26 -> 6045.5 | P26: Online
A27: 26 | B27: 45681 | C27: =TEXT(B27,"mmm") -> Jan | D27: =YEAR(B27) -> 2025 | E27: 9 | F27: Chinedu Adeyemi | G27: 42 | H27: Enugu | I27: South East | J27: 1 | K27: Laptop | L27: Electronics | M27: 83.63 | N27: 4 | O27: =M27*N27 -> 334.52 | P27: Corporate Sales
A28: 27 | B28: 45298 | C28: =TEXT(B28,"mmm") -> Jan | D28: =YEAR(B28) -> 2024 | E28: 104 | F28: Amina Adeyemi | G28: 56 | H28: Port Harcourt | I28: South South | J28: 10 | K28: Laptop Bag | L28: Accessories | M28: 608.48 | N28: 3 | O28: =M28*N28 -> 1825.44 | P28: Online
A29: 28 | B29: 45597 | C29: =TEXT(B29,"mmm") -> Nov | D29: =YEAR(B29) -> 2024 | E29: 114 | F29: Ngozi Yakubu | G29: 18 | H29: Port Harcourt | I29: South South | J29: 27 | K29: Water Bottle | L29: Lifestyle | M29: 845 | N29: 4 | O29: =M29*N29 -> 3380 | P29: Retail Store
A30: 29 | B30: 45721 | C30: =TEXT(B30,"mmm") -> Mar | D30: =YEAR(B30) -> 2025 | E30: 42 | F30: Ada Eze | G30: 45 | H30: Port Harcourt | I30: South South | J30: 23 | K30: Mechanical Keyboard | L30: Gaming | M30: 195.22 | N30: 5 | O30: =M30*N30 -> 976.1 | P30: Online
A31: 30 | B31: 45851 | C31: =TEXT(B31,"mmm") -> Jul | D31: =YEAR(B31) -> 2025 | E31: 2 | F31: Blessing Balogun | G31: 24 | H31: Kano | I31: North West | J31: 30 | K31: Travel Adapter | L31: Lifestyle | M31: 672.22 | N31: 5 | O31: =M31*N31 -> 3361.1 | P31: Marketplace
A32: 31 | B32: 45517 | C32: =TEXT(B32,"mmm") -> Aug | D32: =YEAR(B32) -> 2024 | E32: 60 | F32: Chinedu Mensah | G32: 28 | H32: Lagos | I32: South West | J32: 4 | K32: Headphones | L32: Electronics | M32: 1156.21 | N32: 4 | O32: =M32*N32 -> 4624.84 | P32: Online
A33: 32 | B33: 45516 | C33: =TEXT(B33,"mmm") -> Aug | D33: =YEAR(B33) -> 2024 | E33: 29 | F33: Ngozi Nwosu | G33: 56 | H33: Ibadan | I33: South West | J33: 1 | K33: Laptop | L33: Electronics | M33: 83.63 | N33: 3 | O33: =M33*N33 -> 250.89 | P33: Online
A34: 33 | B34: 45738 | C34: =TEXT(B34,"mmm") -> Mar | D34: =YEAR(B34) -> 2025 | E34: 114 | F34: Ngozi Yakubu | G34: 18 | H34: Port Harcourt | I34: South South | J34: 18 | K34: Webcam | L34: Office | M34: 1209.1 | N34: 4 | O34: =M34*N34 -> 4836.4 | P34: Online
A35: 34 | B35: 45321 | C35: =TEXT(B35,"mmm") -> Jan | D35: =YEAR(B35) -> 2024 | E35: 4 | F35: David Mensah | G35: 50 | H35: Ibadan | I35: South West | J35: 17 | K35: Desk Lamp | L35: Office | M35: 339.98 | N35: 4 | O35: =M35*N35 -> 1359.92 | P35: Retail Store
A36: 35 | B36: 45636 | C36: =TEXT(B36,"mmm") -> Dec | D36: =YEAR(B36) -> 2024 | E36: 11 | F36: Emeka Osei | G36: 52 | H36: Lagos | I36: South West | J36: 10 | K36: Laptop Bag | L36: Accessories | M36: 608.48 | N36: 6 | O36: =M36*N36 -> 3650.88 | P36: Marketplace
A37: 36 | B37: 45987 | C37: =TEXT(B37,"mmm") -> Nov | D37: =YEAR(B37) -> 2025 | E37: 67 | F37: Amina Yakubu | G37: 23 | H37: Abuja | I37: North Central | J37: 29 | K37: Bluetooth Speaker | L37: Lifestyle | M37: 1136.55 | N37: 4 | O37: =M37*N37 -> 4546.2 | P37: Corporate Sales
... A501: 500 | B501: 45565 | C501: =TEXT(B501,"mmm") -> Sept | D501: =YEAR(B501) -> 2024 | E501: 94 | F501: Joseph Bello | G501: 69 | H501: Kano | I501: North West | J501: 25 | K501: Console Stand | L501: Gaming | M501: 705 | N501: 1 | O501: =M501*N501 -> 705 | P501: Retail Store

Sheet Analysis
A3: Row Labels | B3: Sum of Revenue
A4: North West | B4: 193006.29
A5: South South | B5: 232982.1
A6: South East | B6: 253258.06
A7: North Central | B7: 283062.85
A8: South West | B8: 556562.46
A9: Grand Total | B9: 1518871.8
A14: Row Labels | B14: Sum of Revenue
A15: Gaming | B15: 185257.89
A16: Accessories | B16: 199777.15
A17: Electronics | B17: 268173.45
A18: Lifestyle | B18: 268851.01
A19: Office | B19: 289383.36
A20: Home Appliances | B20: 307428.9
A21: Grand Total | B21: 1518871.8
A25: Row Labels | B25: Sum of Revenue
A26: 2024 | B26: 695223.11
A27: 2025 | B27: 823648.65
A28: Grand Total | B28: 1518871.8
A40: Row Labels | B40: Sum of Revenue
A41: Electric Kettle | B41: 113951
A42: Smartphone | B42: 98901.38
A43: Gaming Headset | B43: 88156.16
A44: Printer | B44: 86650.3
A45: Webcam | B45: 85846.1
A46: Grand Total | B46: 473504.94
A55: Sum of Revenue | B55: Average of Revenue | C55: Sum of Quantity | D55: Count of OrderID | E55: Distinct Count of CustomerID
A56: 1518871.8 | B56: 3037.7435 | C56: 1763 | D56: 500 | E56: 117
A59: Sum of Revenue | B59: Column Labels
A60: Row Labels | B60: 2024 | C60: 2025 | D60: Grand Total
A61: Jan | B61: 62445.21 | C61: 45940.51 | D61: 108385.72
A62: Feb | B62: 34598.78 | C62: 67364.9 | D62: 101963.68
A63: Mar | B63: 63008.25 | C63: 70377.87 | D63: 133386.12
A64: Apr | B64: 60556.97 | C64: 102962.53 | D64: 163519.5
A65: May | B65: 56337.24 | C65: 58979.17 | D65: 115316.41
A66: Jun | B66: 45336.63 | C66: 43608.12 | D66: 88944.75
A67: Jul | B67: 34807.16 | C67: 65055.49 | D67: 99862.65
A68: Aug | B68: 59867.07 | C68: 76110.32 | D68: 135977.39
A69: Sept | B69: 49853.6 | C69: 72675.01 | D69: 122528.61
A70: Oct | B70: 89485.95 | C70: 74714.82 | D70: 164200.77
...

Sheet Dashboard
